<?xml version="1.0" encoding="utf-8"?>
<!-- This URDF was automatically created by SolidWorks to URDF Exporter! Originally created by Stephen Brawner (brawner@gmail.com) 
     Commit Version: 1.6.0-4-g7f85cfe  Build Version: 1.6.7995.38578
     For more information, please see http://wiki.ros.org/sw_urdf_exporter -->
<robot
  name="nova_arm">
  <link
    name="base_link">
    <inertial>
      <origin
        xyz="0.0338 0.018286 -0.0073901"
        rpy="0 0 0" />
      <mass
        value="0.7735" />
      <inertia
        ixx="0.0010882"
        ixy="-9.4105E-36"
        ixz="-1.0943E-35"
        iyy="0.001303"
        iyz="-4.8065E-20"
        izz="0.0010882" />
    </inertial>
    <visual>
      <origin
        xyz="0 0 0"
        rpy="0 0 0" />
      <geometry>
        <mesh filename="package://nova_arm/meshes/base_link.STL"/>

      </geometry>
      <material
        name="">
        <color
          rgba="0.79216 0.81961 0.93333 1" />
      </material>
    </visual>
    <collision>
      <origin
        xyz="0 0 0"
        rpy="0 0 0" />
      <geometry>
        <mesh filename="package://nova_arm/meshes/base_link.STL"/>
      </geometry>
    </collision>
  </link>
  <link
    name="Link_1">
    <inertial>
      <origin
        xyz="1.3878E-17 0.046136 -0.0050286"
        rpy="0 0 0" />
      <mass
        value="0.23804" />
      <inertia
        ixx="0.00057347"
        ixy="-9.3723E-20"
        ixz="-8.8938E-21"
        iyy="0.00048732"
        iyz="9.6538E-06"
        izz="0.00037661" />
    </inertial>
    <visual>
      <origin xyz="0 0 0" rpy="1.5708 0 1.5708"/>
      <geometry><mesh filename="package://nova_arm/meshes/Link_1.STL"/></geometry>
      <material name=""><color rgba="0.79216 0.81961 0.93333 1"/></material>
    </visual>

    <collision>
      <origin xyz="0 0 0" rpy="1.5708 0 1.5708"/>
      <geometry><mesh filename="package://nova_arm/meshes/Link_1.STL"/></geometry>
    </collision>
  </link>
  <joint
    name="joint_1"
    type="revolute">
    <origin
      xyz="0 0  0.085"
      rpy="0 0 0" />
    <parent
      link="base_link" />
    <child
      link="Link_1" />
    <axis
      xyz="0 0 1" />
    <limit
      lower="-3.1416"
      upper="3.1416"
      effort="15"
      velocity="1" />
  </joint>
  <link
    name="Link_2">
    <inertial>
      <origin
        xyz="3.4326E-05 1.6537E-05 -0.099338"
        rpy="0 0 0" />
      <mass
        value="0.86019" />
      <inertia
        ixx="0.0080287"
        ixy="2.0422E-07"
        ixz="1.3058E-06"
        iyy="0.0081005"
        iyz="2.0024E-06"
        izz="0.00062811" />
    </inertial>
    <visual>
      <origin xyz="0 0 0" rpy="1.5708 0 -1.5708"/>
      <geometry><mesh filename="package://nova_arm/meshes/Link_2.STL"/></geometry>
      <material name=""><color rgba="0.79216 0.81961 0.93333 1"/></material>
    </visual>

    <collision>
      <origin xyz="0 0 0" rpy="1.5708 0 -1.5708"/>
      <geometry><mesh filename="package://nova_arm/meshes/Link_2.STL"/></geometry>
    </collision>
  </link>
  <joint
    name="joint_2"
    type="revolute">
    <origin
      xyz="0 0 0.066"
      rpy="0 -1.5708 0" />
    <parent
      link="Link_1" />
    <child
      link="Link_2" />
    <axis
      xyz="0 0 1" />
    <limit
      lower="-1.919"
      upper="1.919"
      effort="12"
      velocity="1" />
  </joint>
  <link
    name="Link_3">
    <inertial>
      <origin
        xyz="0.10227 0.012019 -1.8999E-09"
        rpy="0 0 0" />
      <mass
        value="0.27991" />
      <inertia
        ixx="0.00019399"
        ixy="0.00017687"
        ixz="1.3143E-11"
        iyy="0.00079147"
        iyz="-2.5241E-11"
        izz="0.00087188" />
    </inertial>
    <visual>
      <origin xyz="0 0 0" rpy="1.5708  0 0"/>
      <geometry><mesh filename="package://nova_arm/meshes/Link_3.STL"/></geometry>
      <material name=""><color rgba="0.79216 0.81961 0.93333 1"/></material>
    </visual>

    <collision>
      <origin xyz="0 0 0" rpy="1.5708  0 0"/>
      <geometry><mesh filename="package://nova_arm/meshes/Link_3.STL"/></geometry>
    </collision>
  </link>
  <joint
    name="joint_3"
    type="revolute">
    <origin
      xyz="0.20 0 0" 
      rpy="0 0 0"/>  
    <parent
      link="Link_2" />
    <child
      link="Link_3" />
    <axis
      xyz="0 0 1" />
    <limit
      lower="-2.332"
      upper="2.332"
      effort="10"
      velocity="1.5" />
  </joint>
  <link
    name="Link_4">
    <inertial>
      <origin
        xyz="-0.006593 0.012575 0.013127"
        rpy="0 0 0" />
      <mass
        value="0.0054854" />
      <inertia
        ixx="5.575E-07"
        ixy="-5.7528E-17"
        ixz="-5.3784E-08"
        iyy="3.2259E-07"
        iyz="1.0413E-16"
        izz="4.0861E-07" />
    </inertial>
    <visual>
      <origin
        xyz="0 0 0"
        rpy="0 0 0" />
      <geometry>
        <mesh
          filename="package://nova_arm/meshes/Link_4.STL" />
      </geometry>
      <material
        name="">
        <color
          rgba="0.25098 0.25098 0.25098 1" />
      </material>
    </visual>
    <collision>
      <origin
        xyz="0 0 0"
        rpy="0 0 0" />
      <geometry>
        <mesh
          filename="package://nova_arm/meshes/Link_4.STL" />
      </geometry>
    </collision>
  </link>
  <joint
    name="joint_4"
    type="prismatic">
    <origin
      xyz="0.17556 0.0027305 -0.012575"
      rpy="1.5708 0 1.5708" />
    <parent
      link="Link_3" />
    <child
      link="Link_4" />
    <axis
      xyz="-1 0 0" />
    <limit
      lower="0"
      upper="0.014"
      effort="50"
      velocity="0.02" />
  </joint>
  <link
    name="Link_5">
    <inertial>
      <origin
        xyz="-0.006593 0.012575 0.013127"
        rpy="0 0 0" />
      <mass
        value="0.0054854" />
      <inertia
        ixx="5.575E-07"
        ixy="-5.7303E-17"
        ixz="-5.3784E-08"
        iyy="3.2259E-07"
        iyz="1.058E-16"
        izz="4.0861E-07" />
    </inertial>
    <visual>
      <origin
        xyz="0 0 0"
        rpy="0 0 0" />
      <geometry>
        <mesh
          filename="package://nova_arm/meshes/Link_5.STL" />
      </geometry>
      <material
        name="">
        <color
          rgba="0.25098 0.25098 0.25098 1" />
      </material>
    </visual>
    <collision>
      <origin
        xyz="0 0 0"
        rpy="0 0 0" />
      <geometry>
        <mesh
          filename="package://nova_arm/meshes/Link_5.STL" />
      </geometry>
    </collision>
  </link>
  <joint
    name="joint_5"
    type="prismatic">
    <origin
      xyz="0.17556 0.0018695 0.012575"
      rpy="-1.5708 0 -1.5708" />
    <parent
      link="Link_3" />
    <child
      link="Link_5" />
    <axis
      xyz=" 1 0 0" />
    <limit
      lower="-0.014"
      upper="0"
      effort="50"
      velocity="0.02" />
  </joint>

    <ros2_control name="nova_arm_system" type="system">
    <hardware>
      <plugin>gz_ros2_control/GazeboSystem</plugin>
    </hardware>

    <joint name="joint_1">
      <command_interface name="position"/>
      <state_interface name="position"/>
      <state_interface name="velocity"/>
    </joint>
    <joint name="joint_2">
      <command_interface name="position"/>
      <state_interface name="position"/>
      <state_interface name="velocity"/>
    </joint>
    <joint name="joint_3">
      <command_interface name="position"/>
      <state_interface name="position"/>
      <state_interface name="velocity"/>
    </joint>
    <joint name="joint_4">
      <command_interface name="position"/>
      <state_interface name="position"/>
      <state_interface name="velocity"/>
    </joint>
    <joint name="joint_5">
      <command_interface name="position"/>
      <state_interface name="position"/>
      <state_interface name="velocity"/>
    </joint>
  </ros2_control>

</robot>